{
	"schema_version": "1.6.0",
	"id": "RHSA-2024:9481",
	"modified": "2024-11-21T19:46:02Z",
	"published": "2024-11-13T15:29:06Z",
	"related": [
		"CVE-2024-38875",
		"CVE-2024-39329",
		"CVE-2024-39330",
		"CVE-2024-39614"
	],
	"summary": "Red Hat Security Advisory: Red Hat OpenStack Platform 18.0.3 (python-django) security update",
	"severity": [
		{
			"type": "CVSS_V3",
			"score": "CVSS:3.1/AV:N/AC:L/PR:N/UI:N/S:U/C:N/I:N/A:L"
		}
	],
	"affected": [
		{
			"package": {
				"ecosystem": "Red Hat:openstack:18.0::el9",
				"name": "python-django",
				"purl": "pkg:rpm/redhat/python-django"
			},
			"ranges": [
				{
					"type": "ECOSYSTEM",
					"events": [
						{
							"introduced": "0"
						},
						{
							"fixed": "0:3.2.12-8.el9ost"
						}
					]
				}
			],
			"database_specific": {
				"source": "https://security.access.redhat.com/data/osv/RHSA-2024:9481.json"
			}
		},
		{
			"package": {
				"ecosystem": "Red Hat:openstack:18.0::el9",
				"name": "python3-django",
				"purl": "pkg:rpm/redhat/python3-django"
			},
			"ranges": [
				{
					"type": "ECOSYSTEM",
					"events": [
						{
							"introduced": "0"
						},
						{
							"fixed": "0:3.2.12-8.el9ost"
						}
					]
				}
			],
			"database_specific": {
				"source": "https://security.access.redhat.com/data/osv/RHSA-2024:9481.json"
			}
		}
	],
	"references": [
		{
			"type": "ADVISORY",
			"url": "https://access.redhat.com/errata/RHSA-2024:9481"
		},
		{
			"type": "ARTICLE",
			"url": "https://access.redhat.com/security/updates/classification/#moderate"
		},
		{
			"type": "REPORT",
			"url": "https://bugzilla.redhat.com/show_bug.cgi?id=2295935"
		},
		{
			"type": "REPORT",
			"url": "https://bugzilla.redhat.com/show_bug.cgi?id=2295936"
		},
		{
			"type": "REPORT",
			"url": "https://bugzilla.redhat.com/show_bug.cgi?id=2295937"
		},
		{
			"type": "REPORT",
			"url": "https://bugzilla.redhat.com/show_bug.cgi?id=2295938"
		},
		{
			"type": "ADVISORY",
			"url": "https://security.access.redhat.com/data/csaf/v2/advisories/2024/rhsa-2024_9481.json"
		},
		{
			"type": "REPORT",
			"url": "https://access.redhat.com/security/cve/CVE-2024-38875"
		},
		{
			"type": "ADVISORY",
			"url": "https://www.cve.org/CVERecord?id=CVE-2024-38875"
		},
		{
			"type": "ADVISORY",
			"url": "https://nvd.nist.gov/vuln/detail/CVE-2024-38875"
		},
		{
			"type": "REPORT",
			"url": "https://access.redhat.com/security/cve/CVE-2024-39329"
		},
		{
			"type": "ADVISORY",
			"url": "https://www.cve.org/CVERecord?id=CVE-2024-39329"
		},
		{
			"type": "ADVISORY",
			"url": "https://nvd.nist.gov/vuln/detail/CVE-2024-39329"
		},
		{
			"type": "REPORT",
			"url": "https://access.redhat.com/security/cve/CVE-2024-39330"
		},
		{
			"type": "ADVISORY",
			"url": "https://www.cve.org/CVERecord?id=CVE-2024-39330"
		},
		{
			"type": "ADVISORY",
			"url": "https://nvd.nist.gov/vuln/detail/CVE-2024-39330"
		},
		{
			"type": "REPORT",
			"url": "https://access.redhat.com/security/cve/CVE-2024-39614"
		},
		{
			"type": "ADVISORY",
			"url": "https://www.cve.org/CVERecord?id=CVE-2024-39614"
		},
		{
			"type": "ADVISORY",
			"url": "https://nvd.nist.gov/vuln/detail/CVE-2024-39614"
		}
	]
}
