{
	"schema_version": "1.6.0",
	"id": "RHSA-2024:4260",
	"modified": "2024-11-24T15:53:18Z",
	"published": "2024-09-14T03:15:42Z",
	"related": [
		"CVE-2024-3651"
	],
	"summary": "Red Hat Security Advisory: python-idna security update",
	"severity": [
		{
			"type": "CVSS_V3",
			"score": "CVSS:3.1/AV:N/AC:L/PR:L/UI:N/S:U/C:N/I:N/A:H"
		}
	],
	"affected": [
		{
			"package": {
				"ecosystem": "Red Hat:enterprise_linux:8::baseos",
				"name": "python-idna",
				"purl": "pkg:rpm/redhat/python-idna"
			},
			"ranges": [
				{
					"type": "ECOSYSTEM",
					"events": [
						{
							"introduced": "0"
						},
						{
							"fixed": "0:2.5-7.el8_10"
						}
					]
				}
			],
			"database_specific": {
				"source": "https://security.access.redhat.com/data/osv/RHSA-2024:4260.json"
			}
		},
		{
			"package": {
				"ecosystem": "Red Hat:enterprise_linux:8::baseos",
				"name": "python3-idna",
				"purl": "pkg:rpm/redhat/python3-idna"
			},
			"ranges": [
				{
					"type": "ECOSYSTEM",
					"events": [
						{
							"introduced": "0"
						},
						{
							"fixed": "0:2.5-7.el8_10"
						}
					]
				}
			],
			"database_specific": {
				"source": "https://security.access.redhat.com/data/osv/RHSA-2024:4260.json"
			}
		}
	],
	"references": [
		{
			"type": "ADVISORY",
			"url": "https://access.redhat.com/errata/RHSA-2024:4260"
		},
		{
			"type": "ARTICLE",
			"url": "https://access.redhat.com/security/updates/classification/#moderate"
		},
		{
			"type": "REPORT",
			"url": "https://bugzilla.redhat.com/show_bug.cgi?id=2274779"
		},
		{
			"type": "ADVISORY",
			"url": "https://security.access.redhat.com/data/csaf/v2/advisories/2024/rhsa-2024_4260.json"
		},
		{
			"type": "REPORT",
			"url": "https://access.redhat.com/security/cve/CVE-2024-3651"
		},
		{
			"type": "ADVISORY",
			"url": "https://www.cve.org/CVERecord?id=CVE-2024-3651"
		},
		{
			"type": "ADVISORY",
			"url": "https://nvd.nist.gov/vuln/detail/CVE-2024-3651"
		}
	]
}
